Workbook

Sheet SOURCES
K1: il faut donner la possibilliter de prioriser ou numéroter les réponses | L1: https://www.intelligences-multiples.org/intelligences-multiples2/les-8-types-dintelligences/
B2: Soft skills | C2: https://moodwork.com/blog/well-being/liste-des-soft-skills/
B3: MBTI | C3: https://www.windtopik.fr/profil-mbti-affecter-vos-choix-metiers/#Quels_sont_les_types_de_MBTI
B4: Intélligence multiples | C4: https://www.intelligences-multiples.org/intelligences-multiples2/les-8-types-dintelligences/

Sheet Questionnaire 
A1: Questionnaire Soft Skills & MBTI — Version Lycée / Adulte (48 questions) | L1: Sélectionnez A,B,C ou D grâce à la liste déroulante.
A2: Question | B2: Remarque | C2: Soft skill | D2: Catégorie | E2: Classe MBTI | F2: Explication | G2: Question | H2: A | I2: B | J2: C | K2: D | L2: Votre choix | M2: Explication réponse | N2: Point soft skill | O2: Sélection soft skills | P2: Soft skill à développer ? | Q2: remarque affirmation | R2: A | S2: B | T2: C | U2: D | W2: Lettre MBTI (calculée)
A3: {=_xlfn.SEQUENCE(COUNTA(C3:C100))} | C3: Communication écrite | D3: Communication | E3: Energie (E-extraverti ou I-Introverti) | F3: Capacité à être facilement lu et compris mais aussi de susciter l'intérêt lorsque l'on transmet un message par écrit. | G3: Lorsque vous rédigez une note ou un écrit à destination d'autres individus : | H3: Vous ne recevez jamais de retour négatif car vous êtes un expert de la communication écrite. | I3: Vous recevez rarement des retours d'incompréhension. | J3: On comprend mais certains vous signalent qu'il y a beaucoup de fautes de français. | K3: Vous recevez plusieurs messages vous demandant d'être plus explicite parce qu'on ne comprend rien du tout. | L3: A | M3: =_xlfn.XLOOKUP(L3,'Questionnaire '!$R$2:$U$2,'Questionnaire '!R3:U3,,1) | N3: =IF(L3="A",2,IF(L3="B",1,0)) | O3: Soft skills | P3: =IF(N3>=1,"","À développer") | R3: Vous êtes particulièrement doué à l'écrit. | S3: Vous savez aussi vous exprimer à l'écrit. En général, les gens comprennent facilement vos propos quand ils vous lisent. | T3: Vous faites beaucoup de faute de français à l'écrit. | U3: Vous avez certaines difficultés à structurer vos phrases à l'écrit. Vous pouvez faire des fautes de français.
A4: 1 | C4: L’audace (ou le culot) | D4: Communication | E4: Mode d'action ou style de vie (J-Organisation ou P-perception) | F4: Capacité à mettre en place ou réaliser des actions qui semblent risquées, difficiles et/ou irréalisables. | G4: Lors d'une réunion professionnelle, on vous propose soudainement de présenter vos idées sur un projet complexe devant plusieurs supérieurs. Vous n'avez pas préparé de présentation formelle. Comment réagissez-vous ? | H4: J'accepte l'opportunité spontanément, en me fiant à ma connaissance du sujet pour guider ma présentation. | I4: Bien que surpris, je saisis l'occasion de partager mes idées, en improvisant une présentation concise basée sur mes connaissances actuelles. | J4: Je m'excuse en expliquant que je ne suis pas prêt à présenter et je suggère de reporter à un moment où je pourrais mieux me préparer. | K4: La situation me met mal à l'aise, donc je décline poliment, préférant ne pas prendre le risque de me présenter sans préparation. | L4: C | M4: =_xlfn.XLOOKUP(L4,'Questionnaire '!$R$2:$U$2,'Questionnaire '!$R4:$U4) | N4: =IF(L4="A",2,IF(L4="B",1,0)) | O4: Soft skills | P4: =IF(N4>=1,"","À développer") | R4: Vous avez de l'audace et êtes relativement spontané. | S4: Vous avez de l'audace et êtes relativement spontané. | T4: Vous êtes quelqu'un de timide et réservé. | U4: Cependant vous avez peu d'audace ou de culot quand il s'agit de s'adresser aux personnes qui vous semblent impressionnantes. | W4: =IF(N4>0,"N","S")
A5: 2 | C5: La clarté de communication | D5: Communication | E5: Energie (E-extraverti ou I-Introverti) | F5: Capacité à exprimer clairement ses idées lorsque l’on s’adresse à un ou plusieurs individus. | G5: Lorsque vous parlez, devez-vous répéter régulièrement vos phrases pour être parfaitement compris ? | H5: Non, ça ne m'arrive jamais. | I5: Rarement, une fois comme ça. | J5: Ça m'arrive régulièrement. | K5: Ça m'arrive tout le temps, je dois souvent reprendre depuis le début. | M5: =_xlfn.XLOOKUP(L5,'Questionnaire '!$R$2:$U$2,'Questionnaire '!$R5:$U5) | N5: =IF(L5="A",2,IF(L5="B",1,0)) | O5: Soft skills | P5: =IF(N5>=1,"","À développer") | R5: Vous savez vous exprimer extrêmement bien. | S5: Vous êtes clair quand vous vous exprimez à l'oral, ceux qui vous écoutent comprennent facilement vos propos. | T5: Vous avez du mal à vous exprimer correctement. | U5: Vous avez des problèmes d'élocution. Vous avez du mal à structurer des phrases claires et précises. | W5: =IF(N5>0,"E","I")
A6: 3 | C6: La diplomatie | D6: Communication | E6: Prise de décision (T-pensée ou F-sentiment) | F6: Qualité qui permet d'apprécier intuitivement ce qu'il convient de dire, de faire ou d'éviter dans les relations humaines. | G6: Lorsqu'on vous demande de donner votre avis sur un sujet sensible, vous avez tendance à : | H6: Donner votre opinion sans mentir, même si votre avis peut blesser. | I6: Expliquer quels sont les faits, sans chercher à transformer la réalité. | J6: Mesurer votre franchise afin de ne pas créer de malaise. | K6: Bien choisir vos mots afin de ne blesser personne. | M6: =_xlfn.XLOOKUP(L6,'Questionnaire '!$R$2:$U$2,'Questionnaire '!$R6:$U6) | N6: =IF(L6="C",2,IF(L6="D",1,0)) | O6: Soft skills | P6: =IF(N6>=1,"","À développer") | R6: Vous pouvez parfois manquer de diplomatie et de tact quand vous vous adressez aux gens. | S6: Vous aimez relater les faits de façon claire et précise, vous n'aimez pas les discours fallacieux. | T6: Vous avez tendance à éviter de blesser les gens lorsque vous débattez. | U6: Vous êtes extrêmement diplomate dans vos propos, vous cherchez toujours les termes et tournures de phrases les moins choquantes. | W6: =IF(N6>0,"F","T")
A7: 4 | C7: La négociation | D7: Communication | E7: Energie (E-extraverti ou I-Introverti) | F7: Capacité à trouver un accord avec un ou plusieurs partis. | G7: Vous trouvez un objet que vous souhaitiez acheter depuis longtemps, simplement le prix est trop élevé par rapport à votre budget. | H7: Vous contactez le vendeur pour trouver un accord gagnant-gagnant qui satisfait les deux parties. | I7: Vous argumentez sur la valeur réelle de l'objet et ses éventuels défauts pour obtenir un prix plus juste. | J7: Vous allez voir chez un concurrent pour trouver moins cher sans entrer dans une négociation. | K7: Vous préférez attendre d'avoir plus d'argent ou que le prix baisse de lui-même. | M7: =_xlfn.XLOOKUP(L7,'Questionnaire '!$R$2:$U$2,'Questionnaire '!$R7:$U7) | N7: =IF(L7="A",2,IF(L7="B",1,0)) | O7: Soft skills | P7: =IF(N7>=1,"","À développer") | R7: Vous maîtrisez l'art de la négociation. Vous savez construire des accords profitables pour toutes les parties. | S7: Vous savez négocier en vous appuyant sur des arguments concrets pour obtenir un meilleur prix. | T7: Vous évitez la négociation directe et préférez chercher une alternative. | U7: Vous n'aimez pas négocier et préférez attendre que la situation évolue d'elle-même. | W7: =IF(N7>0,"E","I")
A8: 5 | C8: Prise de parole en public | D8: Communication | E8: Energie (E-extraverti ou I-Introverti) | F8: Capacité à s'exprimer devant une foule, ou lors d'événements. | G8: Lorsqu'on vous demande de vous présenter devant une foule de personnes, votre première pensée est : | H8: Super vous allez faire le show, vous êtes pressé d'être sur la scène. | I8: Ça ne me dérange pas, je vais le faire. | J8: Je n’aime pas trop ça, mais je vais quand même essayer. | K8: Ce n'est pas du tout mon truc. Je vais paniquer et perdre mes moyens. | M8: =_xlfn.XLOOKUP(L8,'Questionnaire '!$R$2:$U$2,'Questionnaire '!$R8:$U8) | N8: =IF(L8="A",2,IF(L8="B",1,0)) | O8: Soft skills | P8: =IF(N8>=1,"","À développer") | R8: Vous aimez être le centre de l'attention et vous exprimer en public. | S8: Vous n'avez aucun problème à vous exprimer devant une foule. Vous n'êtes pas timide. | T8: Vous avez aussi tendance à éviter les prises de paroles en public. Ce n'est pas votre truc. | U8: Parler devant une foule vous met mal à l'aise et peut vous stresser. | W8: =IF(N8>0,"E","I")
A9: 6 | C9: Rhétorique ou storytelling | D9: Communication | E9: Energie (E-extraverti ou I-Introverti) | F9: L’art de savoir raconter ou narrer une histoire. | G9: Lorsque vous racontez une histoire, un évènement ou le résumé d'un film : | H9: Les personnes qui écoutent sont captivées et ont envie d'en savoir plus. | I9: Les auditeurs sont attentifs. | J9: Les auditeurs comprennent l’histoire mais ont l'air de s'ennuyer. | K9: Les personnes qui écoutent froncent les sourcils, comme si vous parliez un langage extraterrestre. | M9: =_xlfn.XLOOKUP(L9,'Questionnaire '!$R$2:$U$2,'Questionnaire '!$R9:$U9) | N9: =IF(L9="A",2,IF(L9="B",1,0)) | O9: Soft skills | P9: =IF(N9>=1,"","À développer") | R9: Vous avez un sens de l'art oratoire développé. | S9: Vous savez raconter les histoires et les anecdotes. En général, les gens vous écoutent attentivement. | T9: Vous avez du mal à capter l'attention des autres quand vous vous exprimez. | U9: Vous avez de vraies difficultés à structurer vos pensées et votre discours lorsque vous évoquez un évènement ou des anecdotes. | W9: =IF(N9>0,"E","I")
A10: 7 | C10: Actualisation des connaissances | D10: Esprit critique | E10: Recueil d'information ou perception (S-sensation ou N-intuition) | F10: Capacité à renouveler les connaissances et les compétences acquises. | G10: Lors d'une conversation avec des collègues, un nouveau logiciel révolutionnaire dans votre secteur est mentionné, mais vous ne le connaissez pas. Que faites-vous ensuite ? | H10: Lire les articles et les ouvrages les plus récents sur le sujet et allez aux conférences sur le sujet. | I10: je pose des questions à mes collègues pour en savoir plus, et j'envisage de m'informer davantage par la suite. | J10: Je ne m'en préoccupe pas vraiment, si c'est important, quelqu'un m'en parlera plus en détail. | K10: Je ne suis pas sûr(e) de vouloir investir du temps pour comprendre ce logiciel, s'il ne m'apporte rien immédiatement. | M10: =_xlfn.XLOOKUP(L10,'Questionnaire '!$R$2:$U$2,'Questionnaire '!$R10:$U10) | N10: =IF(L10="A",2,IF(L10="B",1,0)) | O10: Soft skills | P10: =IF(N10>=1,"","À développer") | R10: Vous aimez vous documenter, et cela, même sur un sujet où vous avez déjà une certaine expertise. | S10: Vous aimez vous documenter, et cela, même sur un sujet où vous avez déjà une certaine expertise. | T10: Vous n'êtes pas du type à systématiquement actualiser vos connaissances lorsque vous parlez d'un sujet. Vous préférez utiliser votre expérience et vos souvenirs. | U10: Vous n'êtes pas du type à systématiquement actualiser vos connaissances lorsque vous parlez d'un sujet. Vous préférez utiliser votre expérience et vos souvenirs. | W10: =IF(N10>0,"N","S")
A11: 8 | C11: L’acuité et le discernement | D11: Esprit critique | E11: Recueil d'information ou perception (S-sensation ou N-intuition) | F11: Capacité de l'esprit à juger clairement et sainement des choses | G11: Un de vos amis de confiance partage une publication qui affirme que l'utilisation fréquente des téléphones mobiles peut causer de graves problèmes de santé. Quelle est votre réaction ? | H11: Vous vérifierez l'information en cherchant des sources vraisemblables et des études scientifiques sur le sujet. | I11: Vous lui demandez où il a obtenu cette information. | J11: Vous partagez immédiatement l'information sur vos propres réseaux sociaux pour alerter vos amis et votre famille. | K11: Vous arrêtez d'utiliser votre téléphone mobile par peur des risques pour la santé. | M11: =_xlfn.XLOOKUP(L11,'Questionnaire '!$R$2:$U$2,'Questionnaire '!$R11:$U11) | N11: =IF(L11="A",2,IF(L11="B",1,0)) | O11: Soft skills | P11: =IF(N11>=1,"","À développer") | R11: Vous avez une faculté de discernement élevéee. | S11: Vous avez une faculté de discernement élevéee. | T11: Vous pouvez parfois manquer de discernement quand la situation l'impose. | U11: Vous pouvez parfois manquer de discernement quand la situation l'impose. | W11: =IF(N11>0,"N","S")
A12: 9 | C12: L’ouverture d'esprit | D12: Esprit critique | E12: Mode d'action ou style de vie (J-Organisation ou P-perception) | F12: Tolérer et manifester de l'intérêt, de la curiosité et de la compréhension pour les idées qui diffèrent en partie ou totalement des siennes. | G12: Une nouvelle personne intègre votre groupe de travail. Elle vous informe qu'une des méthodes que vous utilisez est totalement obsolète. | H12: Vous l'envoyez balader. Elle devrait écouter au lieu de critiquer dès son arrivée. | I12: Vous ne changez pas de méthode car elle a déjà fonctionné. | J12: Vous vous renseignez quand même sur les autres méthodes existantes. | K12: Par curiosité vous lui demandez quelle méthode serait la meilleure selon elle. | M12: =_xlfn.XLOOKUP(L12,'Questionnaire '!$R$2:$U$2,'Questionnaire '!$R12:$U12) | N12: =IF(L12="C",2,IF(L12="D",1,0)) | O12: Soft skills | P12: =IF(N12>=1,"","À développer") | R12: Votre ouverture d’esprit s’arrête au moment où vous vous sentez directement visé par les critiques. | S12: Vous pouvez souvent manquer d'ouverture si on remet en question vos capacités ou vos avis. | T12: Vous pouvez vous montrer ouvert d'esprit même quand une personne n'est pas d'accord avec vous sur un sujet qui vous concerne. | U12: Vous pouvez vous montrer ouvert d'esprit même quand une personne n'est pas d'accord avec vous sur certains sujets. | W12: =IF(N12>0,"N","S")
A13: 10 | C13: La créativité ou l'imagination | D13: Esprit critique | E13: Recueil d'information ou perception (S-sensation ou N-intuition) | F13: Faculté de former des images d'objets qui n'ont pas été perçus ou de créer de nouvelles combinaisons d'images ou d'idées, de se représenter des situations possibles. | G13: On vous demande de créer une histoire : | H13: Vous n'arrivez pas à imaginer quoi que ce soit, et vous détestez cet exercice. | I13: Vous demandez de l'aide à une amie qui a plus d'imagination que vous. | J13: Vous arrivez immédiatement à imaginer une trame et quelques personnages. | K13: Vous arrivez tout de suite à imaginer les lieux, l'époque, les costumes, des personnages, les langues, les voix et accents des personnages. | M13: =_xlfn.XLOOKUP(L13,'Questionnaire '!$R$2:$U$2,'Questionnaire '!$R13:$U13) | N13: =IF(L13="C",2,IF(L13="D",1,0)) | O13: Soft skills | P13: =IF(N13>=1,"","À développer") | R13: Vous pouvez souvent manquer d’imagination ou de créativité. | S13: Vous pouvez souvent manquer d’imagination ou de créativité. | T13: Vous êtes quelqu'un de créatif. | U13: Vous êtes quelqu'un de créatif. Vous avez beaucoup d'imagination. | W13: =IF(N13>0,"N","S")
A14: 11 | C14: Pensée critique | D14: Esprit critique | E14: Recueil d'information ou perception (S-sensation ou N-intuition) | F14: Disposition intellectuelle qui permet de raisonner correctement, de tirer des conclusions qui ne soient pas prématurées, mais réfléchies et étayées par des arguments.Capacité à questionner et remettre en cause des préjugés et des opinions "toutes faites". | G14: Vous devez partir en voyage dans un pays pour les vacances. Vous découvrez que le journal télévisé décrit ce pays comme dangereux. | H14: Je vais me renseigner auprès de personnes qui y sont déjà allées, afin d'avoir un avis précis de la situation. | I14: Avant d'acheter mon billet, je vais me renseigner auprès de l'ambassade du pays. | J14: Je vais me fier à l'information transmise par le journal télévisé et changer de destination. | K14: Je préfère me fier à mon intuition pour me décider. | M14: =_xlfn.XLOOKUP(L14,'Questionnaire '!$R$2:$U$2,'Questionnaire '!$R14:$U14) | N14: =IF(L14="A",2,IF(L14="B",1,0)) | O14: Soft skills | P14: =IF(N14>=1,"","À développer") | R14: Vous êtes attentif aux détails et aimez suggérer des améliorations à ce que vous observez. | S14: Vous utilisez plus vos sens que votre intuition pour juger et prendre des décisions. Vous aimez les éléments tangibles aux théories. Vous êtes observateur. | T14: Vous avez tendance à écouter facilement les avis des autres plutôt que vérifier les informations de vous-même. | U14: Vous préférez vous servir de votre intuition plutôt que de vos sens afin d'émettre un jugement. | W14: =IF(N14>0,"N","S")
A15: 12 | C15: Savoir rechercher pour résoudre un problème | D15: Esprit critique | E15: Recueil d'information ou perception (S-sensation ou N-intuition) | F15: Savoir mener des recherches, pour répondre à une question, pour résoudre un problème. | G15: Vous devez assembler un meuble complexe chez vous. Cependant, vous vous rendez compte que vous avez perdu le mode d'emploi. | H15: Vous allez contacter le constructeur ou le magasin afin qu’il vous fournisse le mode d'emploi. | I15: Vous allez rechercher sur internet si vous trouvez des vidéos explicatives. | J15: Vous appelez un expert pour qu'il construise le meuble à votre place. | K15: Vous utilisez votre intuition pour construire le meuble au fur et à mesure, et vous adapter. | M15: =_xlfn.XLOOKUP(L15,'Questionnaire '!$R$2:$U$2,'Questionnaire '!$R15:$U15) | N15: =IF(L15="A",2,IF(L15="B",1,0)) | O15: Soft skills | P15: =IF(N15>=1,"","À développer") | R15: Face à un problème, vous êtes du genre à rechercher toutes les informations pouvant vous permettre de le résoudre avant de demander l'aide d'un expert. | S15: Face à une complexité, vous préférez vous renseigner sur la source du problème pour pouvoir le résoudre. | T15: Vous avez tendance à rapidement demander de l'aide lorsque vous rencontrez un problème complexe. | U15: Face à une complexité, vous préférez vous servir de votre intuition plutôt que de rechercher la source du problème pour pouvoir le résoudre. | W15: =IF(N15>0,"N","S")
A16: 13 | C16: L’intégrité | D16: Ethique | E16: Prise de décision (T-pensée ou F-sentiment) | F16: Capacité à ne pas être corrompu ou influencé, à respecter les règles établis sans tricher. Être droit en toutes circonstances. | G16: Après avoir payé vos achats, vous remarquez que le caissier vous a rendu trop de monnaie. Comment réagissez-vous ? | H16: Je signale l'erreur au caissier et lui rends l'argent en trop. | I16: Je vérifie le montant rendu et, constatant l'erreur, je retourne à la caisse pour rectifier la situation. | J16: Je garde l'argent, car c'est une chance inattendue. | K16: Je garde l'argent, car c'est le caissier qui a fait l'erreur, pas moi. | M16: =_xlfn.XLOOKUP(L16,'Questionnaire '!$R$2:$U$2,'Questionnaire '!$R16:$U16) | N16: =IF(L16="A",2,IF(L16="B",1,0)) | O16: Soft skills | P16: =IF(N16>=1,"","À développer") | R16: Vous avez de l'intégrité. Vous signalez immédiatement l'erreur sans hésiter.. | S16: Vous avez de l'intégrité. Vous vérifiez et rectifiez l'erreur, même si personne ne vous a vu.. | T16: Vous manquez d'intégrité. Vous gardez l'argent sans hésiter.. | U16: Vous manquez d'intégrité. Vous gardez l'argent sans hésiter.. | W16: =IF(N16>0,"F","T")
A17: 14 | C17: La conscience professionnelle | D17: Ethique | E17: Prise de décision (T-pensée ou F-sentiment) | F17: Être soigneux et appliqué dans la réalisation d’une tâche ou d'un projet, d'un travail peu importe son état mental. | G17: Vous avez un travail de groupe important à finir pour le lendemain. Votre meilleur(e) ami(e) vous appelle, en vous expliquant qu'il/elle part 6 mois au Mexique et qu'il/elle aimerait passer sa dernière soirée avec vous. | H17: Vous terminez votre travail dans les délais prévus, en gérant votre émotion pour ne pas impacter le groupe. | I17: Vous faites une courte pause pour prendre des nouvelles, puis vous reprenez immédiatement votre travail afin de respecter l'engagement collectif. | J17: Vous lâchez tout pour rejoindre votre ami(e), car vous estimez que l'amitié passe avant tout. | K17: Vous demandez aux autres membres du groupe de finir sans vous, car le travail ne doit pas prendre le dessus sur les relations humaines. | M17: =_xlfn.XLOOKUP(L17,'Questionnaire '!$R$2:$U$2,'Questionnaire '!$R17:$U17) | N17: =IF(L17="A",2,IF(L17="B",1,0)) | O17: Soft skills | P17: =IF(N17>=1,"","À développer") | R17: Vous avez une conscience professionnelle très développée. Vous savez gérer vos émotions pour honorer vos engagements. | S17: Vous avez une bonne conscience professionnelle. Vous trouvez un équilibre entre vos engagements et votre vie personnelle. | T17: Votre conscience professionnelle est peu développée. Vous avez du mal à respecter vos engagements quand la vie personnelle s'invite. | U17: Vous manquez de conscience professionnelle. Vous n'hésitez pas à reporter vos responsabilités sur les autres. | W17: =IF(N17>0,"F","T")
A18: 15 | C18: La loyauté | D18: Ethique | E18: Prise de décision (T-pensée ou F-sentiment) | F18: Capacité à respecter les engagements fixés et être fidèle envers un organisme, un ou plusieurs individus, une loi, une doctrine, une croyance une religion…etc. | G18: Vous devez réaliser un travail de groupe entre amis. Cependant, le groupe de travail sympathique dans lequel vous êtes ne fonctionne pas du tout. Votre réaction : | H18: Vous restez dans le groupe et cherchez à les remotiver, les aider à s'organiser pour améliorer la performance collective. | I18: Vous restez fidèle au groupe et compensez leur manque en travaillant davantage pour ne pas les laisser tomber. | J18: Vous les quittez pour intégrer un groupe plus performant, car vous ne voulez pas être pénalisé par eux. | K18: Vous préférez travailler seul pour être sûr que le travail soit bien fait. | M18: =_xlfn.XLOOKUP(L18,'Questionnaire '!$R$2:$U$2,'Questionnaire '!$R18:$U18) | N18: =IF(L18="A",2,IF(L18="B",1,0)) | O18: Soft skills | P18: =IF(N18>=1,"","À développer") | R18: Vous êtes quelqu'un de loyal et de fédérateur. Vous ne lâchez pas les gens et cherchez à les faire progresser. | S18: Vous êtes loyal. Vous préférez rester fidèle à votre groupe et compenser plutôt que de les abandonner. | T18: Votre loyauté est limitée. Vous êtes prêt à abandonner le groupe dès que cela ne vous avantage plus. | U18: Vous n'êtes pas particulièrement loyal en groupe. Vous préférez votre réussite personnelle à la cohésion collective. | W18: =IF(N18>0,"F","T")
A19: 16 | C19: Le sens des responsabilités | D19: Ethique | E19: Prise de décision (T-pensée ou F-sentiment) | F19: Aptitude à s'assurer de la qualité des actions entreprises et en assumer les conséquences, qu'elles soient bonnes ou mauvaises. | G19: En jouant au foot près d'une maison vous brisez une fenêtre. Tous vos amis se mettent à courir, votre réaction : | H19: Je m'enfuis aussi. Il serait bête de rester là et se faire attraper. Pas vu pas pris. | I19: Je fais comme si je ne jouais pas au foot et j'indique que le coupable est parti en courant. | J19: J’attends dehors afin de me dénoncer. Si on doit me sanctionner on me sanctionnera. | K19: Je me dirige vers la maison pour m'excuser et trouver un moyen de réparer l'erreur. | M19: =_xlfn.XLOOKUP(L19,'Questionnaire '!$R$2:$U$2,'Questionnaire '!$R19:$U19) | N19: =IF(L19="C",2,IF(L19="D",1,0)) | O19: Soft skills | P19: =IF(N19>=1,"","À développer") | R19: Vous n'aimez pas vous mettre en danger, même quand vous êtes le responsable des tracas. | S19: Vous n'aimez pas vous mettre en danger, même quand vous êtes le responsable des tracas. | T19: Vous avez le sens des responsabilités et souhaitez souvent assumer vos erreurs. | U19: Vous avez le sens des responsabilités et souhaitez souvent assumer vos erreurs. | W19: =IF(N19>0,"F","T")
A20: 17 | C20: L'éco-responsabilité | D20: Ethique | E20: Prise de décision (T-pensée ou F-sentiment) | F20: Respecter les règles de protection de l'environnement | G20: Vous avez la possibilité d'acheter une voiture, vous avez le choix entre plusieurs possibilités : | H20: Je préfère acheter un vélo ou une trottinette électrique, car c'est le choix le moins polluant. | I20: J'achète une voiture 100% électrique, pour réduire au maximum mon impact environnemental. | J20: J'achète une voiture simple, fiable et durable qui correspond à mes besoins du quotidien. | K20: J'achète une grosse voiture à essence puissante, car ce qui compte c'est le plaisir de conduire. | M20: =_xlfn.XLOOKUP(L20,'Questionnaire '!$R$2:$U$2,'Questionnaire '!$R20:$U20) | N20: =IF(L20="A",2,IF(L20="B",1,0)) | O20: Soft skills | P20: =IF(N20>=1,"","À développer") | R20: Vous avez une forte conscience écologique. Vous faites des choix radicaux pour limiter votre impact sur l'environnement. | S20: Vous êtes éco-responsable. Vous faites des choix de mobilité en tenant compte de l'impact environnemental. | T20: Vous avez une conscience écologique modérée. Vous faites des choix pratiques sans priorité environnementale marquée. | U20: Vous avez peu de conscience écologique. Votre choix de mobilité ne tient pas compte de l'impact environnemental. | W20: =IF(N20>0,"F","T")
A21: 18 | C21: Respect des autres (doublon tolérance) | D21: Ethique | E21: Prise de décision (T-pensée ou F-sentiment) | F21: Avoir de la considération pour les idées, les opinions, les sentiments, les croyances, les coutumes d'un ou plusieurs individus sans émettre de jugement à leur encontre. | G21: Pourriez-vous prendre en considération une opinion qui bafoue vos principes, vos croyances et/ou votre culture ? | H21: Oui, c'est tout à fait possible. | I21: Oui, ça ne me dérange pas. | J21: Non, je ne préfère pas. | K21: Non, c'est tout à fait impossible. | M21: =_xlfn.XLOOKUP(L21,'Questionnaire '!$R$2:$U$2,'Questionnaire '!$R21:$U21) | N21: =IF(L21="A",2,IF(L21="B",1,0)) | O21: Soft skills | P21: =IF(N21>=1,"","À développer") | R21: Vous êtes tolérant envers les autres et prenez en considération leur avis même s'ils sont à l'opposé de vos croyances.. | S21: Vous êtes tolérant envers les autres et prenez en considération leur avis même s'ils sont à l'opposé de vos croyances.. | T21: Vous pouvez souvent faire preuve d'intolérance quant aux avis des autres. | U21: Vous pouvez souvent faire preuve d'intolérance quant aux avis des autres, surtout quand ils sont en contradiction avec les vôtres. | W21: =IF(N21>0,"F","T")
A22: 19 | C22: Acceptation des retours et critiques | D22: Intelligence émotionnelle | E22: Prise de décision (T-pensée ou F-sentiment) | F22: Capacité à recevoir des critiques constructives sans se vexer. | G22: Vous avez mis 3 mois à réaliser un dossier complexe, vous le montrez à un inconnu qui juge les résultats déplorables. | H22: Vous vous empressez de noter ses commentaires afin de comprendre ce qui ne va pas. | I22: Ça vous énerve, mais vous savez qu'aucun travail n'est parfait donc vous écoutez. | J22: Vous l'ignorez tout simplement, cette personne vous veut du mal. | K22: Vous l'envoyez valser, il ne sait pas à quel point vous vous êtes appliqué(e) dans votre travail. | M22: =_xlfn.XLOOKUP(L22,'Questionnaire '!$R$2:$U$2,'Questionnaire '!$R22:$U22) | N22: =IF(L22="A",2,IF(L22="B",1,0)) | O22: Soft skills | P22: =IF(N22>=1,"","À développer") | R22: Votre recherche d'amélioration vous permet d'apprécier et étudier les critiques. | S22: Les critiques vous irritent, mais vous préférez les écouter que de perdre un moyen de vous améliorer. | T22: Vous détestez être critiqué, surtout par des inconnus. | U22: Vous détestez être critiqué, surtout par des inconnus. | W22: =IF(N22>0,"F","T")
A23: 20 | C23: Introspection | D23: Intelligence émotionnelle | E23: Prise de décision (T-pensée ou F-sentiment) | F23: Aptitude à analyser ses propres émotions, ses aptitudes, ses faiblesses dans le but de se perfectionner. | G23: Si on vous demande de citer vos qualités et vos défauts, y arrivez-vous facilement ? | H23: Non, je n'y arrive jamais. | I23: En général, j'ai besoin qu'on m'aide à le faire. | J23: Plutôt oui. | K23: Oui, j'y arrive très facilement. | M23: =_xlfn.XLOOKUP(L23,'Questionnaire '!$R$2:$U$2,'Questionnaire '!$R23:$U23) | N23: =IF(L23="C",2,IF(L23="D",1,0)) | O23: Soft skills | P23: =IF(N23>=1,"","À développer") | R23: Vous avez des difficultés à expliquer qui vous êtes vraiment. Comme si vous ne vous connaissiez pas réellement.. | S23: Vous avez des difficultés à expliquer qui vous êtes vraiment. Comme si vous ne vous connaissiez pas réellement.. | T23: Vous arrivez à comprendre vos émotions et à les expliquer, mais pas facilement. | U23: Vous arrivez à comprendre vos émotions et à les expliquer facilement. | W23: =IF(N23>0,"F","T")
A24: 21 | C24: L’empathie | D24: Intelligence émotionnelle | E24: Energie (E-extraverti ou I-Introverti) | F24: Capacité à ressentir les émotions d’autres individus (joie, tristesse, honte, frustration, etc.). | G24: Vous assistez à un spectacle, l'un des acteurs oublie son texte et ne sait plus quoi dire. C'est le silence | H24: Vous ressentez une forte gêne et avez envie de l'aider en lui soufflant son texte ou en applaudissant pour l'encourager. | I24: Vous vous sentez mal à l'aise et ressentez profondément son embarras, comme si vous étiez à sa place. | J24: Vous trouvez la situation comique et cela vous fait sourire. | K24: Vous êtes déçu par sa prestation et trouvez cela peu professionnel. | M24: =_xlfn.XLOOKUP(L24,'Questionnaire '!$R$2:$U$2,'Questionnaire '!$R24:$U24) | N24: =IF(L24="A",2,IF(L24="B",1,0)) | O24: Soft skills | P24: =IF(N24>=1,"","À développer") | R24: Vous êtes très empathique. Vous ressentez les émotions des autres et avez le réflexe d'agir pour les soutenir. | S24: Vous êtes empathique. Vous savez vous mettre à la place des autres et ressentir ce qu'ils vivent. | T24: Votre empathie est peu développée. Vous avez du mal à ressentir les émotions des autres et prenez du recul. | U24: Vous manquez d'empathie. Vous jugez les situations de façon détachée sans vous mettre à la place des autres. | W24: =IF(N24>0,"E","I")
A25: 22 | C25: La confiance en soi | D25: Intelligence émotionnelle | E25: Energie (E-extraverti ou I-Introverti) | F25: Avoir toujours confiance en ses capacités ou ses actions. | G25: Vous avez l'opportunité de diriger un projet important au travail. Cela implique de prendre des décisions clés et de gérer une équipe. | H25: Je suis excité(e) par le défi et confiant(e) dans ma capacité à diriger le projet et à prendre les bonnes décisions. | I25: Même si je ressens une certaine pression, je suis sûr(e) de mes compétences et prêt(e) à assumer ce rôle de leadership. | J25: Je suis inquiet(e) à l'idée de ne pas être à la hauteur et j'hésite à accepter le rôle. | K25: La peur de l'échec me pousse à envisager de décliner l'offre, même si une partie de moi sait que je suis capable. | M25: =_xlfn.XLOOKUP(L25,'Questionnaire '!$R$2:$U$2,'Questionnaire '!$R25:$U25) | N25: =IF(L25="A",2,IF(L25="B",1,0)) | O25: Soft skills | P25: =IF(N25>=1,"","À développer") | R25: Vous débordez de confiance en vous, ce qui peut vous rendre téméraire parfois. | S25: En général, vous avez confiance en vos capacités. Vous êtes courageux dans ce que vous entreprenez | T25: Vous manquez parfois de confiance en vos capacités. | U25: Vous manquez parfois de confiance en vos capacités. | W25: =IF(N25>0,"E","I")
A26: 23 | C26: La gestion du stress | D26: Intelligence émotionnelle | E26: Mode d'action ou style de vie (J-Organisation ou P-perception) | F26: Capacité à supporter la pression liée à la réalisation d’une ou plusieurs tâches sans paniquer (examens, projets, demandes hiérarchiques, présentations, etc.). | G26: Une heure avant une présentation orale importante, votre ordinateur plante et vous perdez tous vos documents. Votre réaction : | H26: Vous déprimez et perdez vos moyens car tout est fini. Vous avez les larmes aux yeux. | I26: Vous faites tout pour annuler la présentation car vous ne pourrez pas vous souvenir de tout. | J26: Vous prenez une respiration, et tentez de reproduire votre présentation en puisant dans vos souvenirs. | K26: Vous y allez au talent. Ça passe ou ça casse. | M26: =_xlfn.XLOOKUP(L26,'Questionnaire '!$R$2:$U$2,'Questionnaire '!$R26:$U26) | N26: =IF(L26="C",2,IF(L26="D",1,0)) | O26: Soft skills | P26: =IF(N26>=1,"","À développer") | R26: Vous avez du mal à supporter les situations de stress intenses. Au point de perdre vos moyens. | S26: Vous avez du mal à supporter les situations de stress intenses. Au point de perdre vos moyens. | T26: Vous savez gérer vos émotions dans une situation stressantes. | U26: Vous pouvez être décalé en situation de stress, comme si vous étiez insensible à la situation. | W26: =IF(N26>0,"N","S")
A27: 24 | C27: La sensibilité | D27: Intelligence émotionnelle | E27: Prise de décision (T-pensée ou F-sentiment) | F27: Aptitude à s'émouvoir, à éprouver des sentiments d'humanité, de compassion, de tendresse envers autrui, autre chose ou un évènement. | G27: Vous venez d'apprendre que la femme d'un voisin, avec qui vous avez peu d'affinités, vient d'être hospitalisée dans un état grave, vous êtes du genre à : | H27: À ne rien ressentir, car vous n'êtes pas très proche de votre voisin. | I27: À ne pas vouloir vous mêler de ce qui ne vous regarde pas. | J27: À vouloir pleurer quand vous voyez votre voisin triste et désespéré. | K27: À vouloir l'aider et le réconforter même si vous n'êtes pas très proche. | M27: =_xlfn.XLOOKUP(L27,'Questionnaire '!$R$2:$U$2,'Questionnaire '!$R27:$U27) | N27: =IF(L27="C",2,IF(L27="D",1,0)) | O27: Soft skills | P27: =IF(N27>=1,"","À développer") | R27: Vous pouvez parfois manquer de sensibilité sur des sujets que d'autres trouveraient émouvant. | S27: Vous n'êtes pas quelqu'un que l'on peut émouvoir facilement.. | T27: Vous êtes quelqu'un de sensible et on peut vous émouvoir facilement. | U27: Vous êtes quelqu'un de sensible et on peut vous émouvoir facilement. | W27: =IF(N27>0,"F","T")
A28: 25 | C28: Altruisme | D28: Intelligence sociale | E28: Energie (E-extraverti ou I-Introverti) | F28: Capacité à se soucier du bien des autres et de s'y consacrer de façon désintéressée. | G28: Vous vous rendez compte que vous êtes le seul à avoir bien noté les informations liées à un examen important. | H28: Vous les partagez immédiatement avec tous ceux qui doivent passer l'examen, sans distinction. | I28: Vous les partagez en priorité avec ceux qui ont des difficultés dans la matière, pour les aider à réussir. | J28: Vous les partagez avec ceux qui pourraient vous apporter quelque chose en retour. | K28: Vous gardez cette information pour vous afin d'avoir un avantage sur les autres. | M28: =_xlfn.XLOOKUP(L28,'Questionnaire '!$R$2:$U$2,'Questionnaire '!$R28:$U28) | N28: =IF(L28="A",2,IF(L28="B",1,0)) | O28: Soft skills | P28: =IF(N28>=1,"","À développer") | R28: Vous êtes très altruiste. Vous partagez sans réfléchir et sans condition, car vous voulez que tout le monde réussisse. | S28: Vous êtes altruiste, avec une attention particulière pour ceux qui en ont le plus besoin. | T28: Votre altruisme est conditionnel. Vous aidez si vous pouvez en tirer quelque chose. | U28: Vous n'êtes pas altruiste. Vous préférez garder vos avantages pour vous. | W28: =IF(N28>0,"E","I")
A29: 26 | C29: Esprit d'équipe | D29: Intelligence sociale | E29: Energie (E-extraverti ou I-Introverti) | F29: Aptitude à faire preuve d'altruisme et de solidarité avec les membres de son groupe. | G29: Vous devez réaliser un travail, mais il sera pris en compte uniquement si vous le réalisez en groupe, votre réaction : | H29: Vous êtes heureux de pouvoir travailler à plusieurs, c'est plus amusant. | I29: Vous êtes pressé(e) de connaître vos futurs collaborateurs. | J29: Vous le faites mais uniquement parce que vous n'avez pas le choix. Sinon, vous auriez évité. | K29: Cette idée vous fatigue déjà. Vous détestez les travaux de groupe. | M29: =_xlfn.XLOOKUP(L29,'Questionnaire '!$R$2:$U$2,'Questionnaire '!$R29:$U29) | N29: =IF(L29="A",2,IF(L29="B",1,0)) | O29: Soft skills | P29: =IF(N29>=1,"","À développer") | R29: Vous aimez le travail en équipe. | S29: Vous aimez le travail en équipe tant que vous avez des affinité avec vos collaborateurs. | T29: Vous êtes du genre à travailler en équipe uniquement si cela est nécessaire.. Dans le cas contraire non. | U29: Vous êtes du genre à travailler en équipe uniquement si cela est nécessaire.. Dans le cas contraire non. | W29: =IF(N29>0,"E","I")
A30: 27 | C30: Intelligence culturelle | D30: Intelligence sociale | E30: Energie (E-extraverti ou I-Introverti) | F30: Capacité de s'adapter à différents contextes ou groupes culturels. | G30: Si vous deviez aller dans un pays étranger en vacances, vous seriez : | H30: La personne qui va essayer de parler la langue, apprendre les coutumes, aborder les styles vestimentaires. | I30: La personne qui va vouloir aller dormir chez les gens, aller visiter les lieux historiques. | J30: Celle qui va préférer aller au Macdonald à la place de découvrir la cuisine locale. | K30: La personne qui va préférer rester à l'hôtel pour profiter du calme et de la piscine un maximum. | M30: =_xlfn.XLOOKUP(L30,'Questionnaire '!$R$2:$U$2,'Questionnaire '!$R30:$U30) | N30: =IF(L30="A",2,IF(L30="B",1,0)) | O30: Soft skills | P30: =IF(N30>=1,"","À développer") | R30: Vous avez un attrait pour la découverte d'autres cultures et d'autres langues. | S30: Vous avez un attrait pour la découverte d'autres cultures et d'autres langues. | T30: Vous n'avez pas la particularité de vouloir découvrir d'autres cultures ou apprendre d'autres langues si ce n'est pas nécessaire. | U30: Vous n'avez pas la particularité de vouloir découvrir d'autres cultures ou apprendre d'autres langues si ce n'est pas nécessaire. | W30: =IF(N30>0,"E","I")
A31: 28 | C31: La coopération, la collaboration | D31: Intelligence sociale | E31: Energie (E-extraverti ou I-Introverti) | F31: Aptitude à travailler avec un ou plusieurs autres individus dans le but d'une réalisation commune. | G31: Avez-vous une facilité à collaborer avec des personnes avec qui vous n'avez aucunes affinités ? | H31: Oui, je m'adapte à n'importe quel profil et je sais travailler efficacement avec tout le monde, quelles que soient mes affinités. | I31: Oui, tant qu'on se respecte mutuellement, on peut collaborer sans nécessairement s'apprécier. | J31: Pas vraiment, il me faut un minimum de points communs pour travailler sereinement avec quelqu'un. | K31: Non, j'ai besoin d'apprécier les personnes avec qui je travaille pour être efficace. | M31: =_xlfn.XLOOKUP(L31,'Questionnaire '!$R$2:$U$2,'Questionnaire '!$R31:$U31) | N31: =IF(L31="A",2,IF(L31="B",1,0)) | O31: Soft skills | P31: =IF(N31>=1,"","À développer") | R31: Vous avez une excellente capacité de coopération. Vous savez mettre de côté vos affinités personnelles pour travailler avec n'importe qui. | S31: Vous savez coopérer avec des personnes que vous n'appréciez pas forcément, tant qu'il y a un respect mutuel. | T31: Votre capacité de coopération est limitée. Vous avez besoin d'un minimum d'affinités pour bien travailler avec quelqu'un. | U31: Vous avez du mal à collaborer avec des personnes que vous n'appréciez pas. Cela peut limiter votre efficacité en équipe. | W31: =IF(N31>0,"E","I")
A32: 29 | C32: Le networking | D32: Intelligence sociale | E32: Energie (E-extraverti ou I-Introverti) | F32: Capacité à nouer et maintenir des liens avec d'autres individus et de se créer un réseau sur le long terme. | G32: Aimez-vous nouer des liens avec les gens et entretenir les relations sur le long terme ? | H32: Oui carrément j'adore ça, et je le fais très bien. | I32: Plutôt oui, mais je ne suis pas encore expert en la matière. | J32: Non pas du tout, je préfère avoir un petit groupe d'amis. | K32: Non, je préfère être seul. | M32: =_xlfn.XLOOKUP(L32,'Questionnaire '!$R$2:$U$2,'Questionnaire '!$R32:$U32) | N32: =IF(L32="A",2,IF(L32="B",1,0)) | O32: Soft skills | P32: =IF(N32>=1,"","À développer") | R32: Vous prenez du plaisir à créer une communauté ou un réseau autour de vous. Vous êtes du genre à vous faire des amis rapidement. | S32: Vous prenez du plaisir à créer une communauté ou un réseau autour de vous. Vous êtes du genre à vous faire des amis rapidement. | T32: Vous préférez avoir un petit groupe d'amis plutôt qu’une multitude de connaissances. Ce qui peut vous empêcher d’avoir un réseau de connaissances large. | U32: Vous êtes quelqu'un de solitaire. | W32: =IF(N32>0,"E","I")
A33: 30 | C33: Sociabilité | D33: Intelligence sociale | E33: Energie (E-extraverti ou I-Introverti) | F33: Capacité à vivre en société ou avec un groupe d'individu. Recherche de compagnie. | G33: Lorsque vous devez aller en soirée ou à un anniversaire vous êtes du genre à : | H33: Aller parler à tout le monde car vous voulez absolument savoir qui est qui. | I33: Lancer les conversations même si vous n'y êtes pas obligé. | J33: A chercher un moyen de vous échapper pour éviter de parler aux gens. | K33: Essayer de ne pas aller en soirée ou aux anniversaires. | M33: =_xlfn.XLOOKUP(L33,'Questionnaire '!$R$2:$U$2,'Questionnaire '!$R33:$U33) | N33: =IF(L33="A",2,IF(L33="B",1,0)) | O33: Soft skills | P33: =IF(N33>=1,"","À développer") | R33: Vous êtes extrêmement sociable.. | S33: Vous n'aimez pas les moments de silence et de gène. Votre sociabilité vous incite à lancer les conversations. | T33: Vous n'êtes pas quelqu'un de très sociable. | U33: Vous n'êtes pas quelqu'un de très sociable. | W33: =IF(N33>0,"E","I")
A34: 31 | B34: Etats d'esprit et attitude | C34: L’Autonomie | D34: Management de projet | E34: Mode d'action ou style de vie (J-Organisation ou P-perception) | F34: Ne pas avoir besoin d’accompagnement lorsque l’on entreprend une action. | G34: Lorsqu'on vous confie un projet ou une tâche sans instructions détaillées, comment procédez-vous ? | H34: Je me fixe mes propres objectifs et échéances, j'organise mon travail de façon autonome et je cherche les ressources nécessaires par moi-même.. | I34: Je recherche des informations en ligne — tutoriels, forums, articles — pour trouver comment réaliser le travail au mieux. | J34: Je préfère me faire accompagner par un expert pour être sûr que le travail soit bien réalisé. | K34: Je demande de l'aide à des amis ou collègues qui s'y connaissent mieux que moi. | M34: =_xlfn.XLOOKUP(L34,'Questionnaire '!$R$2:$U$2,'Questionnaire '!$R34:$U34) | N34: =IF(L34="A",2,IF(L34="B",1,0)) | O34: Soft skills | P34: =IF(N34>=1,"","À développer") | R34: Vous êtes très autonome. Vous savez vous organiser, vous fixer des objectifs et trouver les ressources nécessaires sans aide extérieure. | S34: Vous êtes autonome. Vous n'hésitez pas à chercher par vous-même les informations dont vous avez besoin pour avancer. | T34: Votre autonomie est limitée. Vous avez besoin d'être accompagné pour réaliser des tâches sans instructions détaillées. | U34: Vous manquez d'autonomie. Vous cherchez rapidement de l'aide plutôt que d'essayer de trouver des solutions par vous-même. | W34: =IF(N34>0,"N","S")
A35: 32 | C35: La fixation d'objectifs | D35: Management de projet | E35: Prise de décision (T-pensée ou F-sentiment) | F35: Capacité à fixer des objectifs spécifiques, mesurables, atteignables, réalistes et temporels. | G35: Vous envisagez d'apprendre une nouvelle langue cette année. Comment prévoyez-vous de gérer ce projet ? | H35: Je planifie un certain nombre d'heures par semaine à l'étude de la langue et je fixe des délais pour évaluer mes progrès, comme maîtriser les bases d'ici trois mois. | I35: Je m'inscris à un cours en ligne et je me fixe des objectifs clairs, par exemple atteindre un niveau intermédiaire en six mois, en suivant régulièrement les leçons et en pratiquant quotidiennement. | J35: J'achète des livres de langue et des applications, mais sans plan précis sur comment et quand les utiliser. | K35: J'ai l'intention d'apprendre quand j'ai du temps libre, sans me fixer d'objectifs ou de calendrier spécifiques. | M35: =_xlfn.XLOOKUP(L35,'Questionnaire '!$R$2:$U$2,'Questionnaire '!$R35:$U35) | N35: =IF(L35="A",2,IF(L35="B",1,0)) | O35: Soft skills | P35: =IF(N35>=1,"","À développer") | R35: Vous n'aimez pas vous fixer des objectifs qui vous semblent disproportionnés par rapport à vos capacités. Vous êtes réaliste. | S35: Vous n'aimez pas vous fixer des objectifs qui vous semblent disproportionnés par rapport à vos capacités. Vous êtes réaliste. | T35: Vous êtes très ambitieux. Cependant, vous avez tendance à vous fixer des objectifs sans prendre en compte vos capacités réelles. | U35: Vous êtes très ambitieux. Cependant, vous avez tendance à vous fixer des objectifs sans prendre en compte vos capacités réelles. | W35: =IF(N35>0,"F","T")
A36: 33 | C36: La gestion des risques | D36: Management de projet | E36: Prise de décision (T-pensée ou F-sentiment) | F36: Capacité à lister et évaluer les scénarios problématiques et trouver des solutions pouvant les résoudre. | G36: Lorsque l'on met en place un projet, quel qu’il soit, que faut-il prendre en compte en premier lieu ? | H36: Les divers évènements qui pourraient faire en sorte que le projet soit annulé. | I36: Avoir un plan de secours pour chaque imprévu. | J36: Que la qualité de l'évènement soit bien au rendez-vous. | K36: L’avis des participants, car l'essentiel c'est que ça leurs plaise. | M36: =_xlfn.XLOOKUP(L36,'Questionnaire '!$R$2:$U$2,'Questionnaire '!$R36:$U36) | N36: =IF(L36="A",2,IF(L36="B",1,0)) | O36: Soft skills | P36: =IF(N36>=1,"","À développer") | R36: Vous préférez prévoir les évènements néfastes d’un projet avant de le commencer, par peur de ne pas le mener à bien. | S36: Vous préférez prévoir les évènements néfastes d’un projet avant de le commencer, par peur de ne pas le mener à bien. | T36: Vous n'êtes pas du genre à vouloir prévoir les évènements nuisibles. Vous préférez réagir aux conséquences que les prévenir. | U36: Vous n'êtes pas du genre à vouloir prévoir les évènements nuisibles. Vous préférez réagir aux conséquences que les prévenir. | W36: =IF(N36>0,"F","T")
A37: 34 | C37: La prise de décision | D37: Management de projet | E37: Prise de décision (T-pensée ou F-sentiment) | F37: Aptitude à effectuer un choix entre plusieurs modalités d'actions possibles lors de la confrontation à un problème. | G37: Il reste 3 mois à vivre à une personne que vous aimez. Un médecin propose une solution qui pourrait prolonger sa vie de 10 ans en cas de réussite, ou le tuer en cas d'échec. | H37: Vous lisez toutes les études disponibles sur l'opération, évaluez les risques et bénéfices, puis prenez votre décision de façon éclairée. | I37: Vous prenez la décision de mettre en place la solution, car face à l'urgence, il vaut mieux agir que d'attendre. | J37: Vous réunissez les proches pour décider collectivement, car une telle décision ne doit pas reposer sur une seule personne. | K37: Vous ne parvenez pas à prendre de décision, car l'enjeu est trop lourd à porter. | M37: =_xlfn.XLOOKUP(L37,'Questionnaire '!$R$2:$U$2,'Questionnaire '!$R37:$U37) | N37: =IF(L37="A",2,IF(L37="B",1,0)) | O37: Soft skills | P37: =IF(N37>=1,"","À développer") | R37: Vous prenez vos décisions difficiles avec rigueur et méthode. Vous vous informez avant d'agir, même sous pression. | S37: Vous savez prendre des décisions difficiles et les assumer, même quand elles comportent une part d'incertitude. | T37: Vous avez du mal à prendre seul des décisions difficiles. Vous cherchez à diluer la responsabilité. | U37: Vous avez des difficultés à prendre des décisions sous pression. La peur de vous tromper vous paralyse. | W37: =IF(N37>0,"F","T")
A38: 35 | C38: La supervision | D38: Management de projet | E38: Mode d'action ou style de vie (J-Organisation ou P-perception) | F38: Capacité à exercer un contrôle et à effectuer une vérification sur l'activité ou le travail d'une ou plusieurs personnes. | G38: Lorsque vous effectuez un travail de groupe, ce que vous préférez c'est : | H38: Etablir des outils qui permettront de contrôler l'avancée des travaux. | I38: Vérifier au fur et à mesure que les tâches ont bien été réalisées | J38: Terminer vite, contrôler la qualité, et ensuite tout corriger. | K38: Réaliser en premier lieu les tâches qui vous plaisent le plus et les autres ensuite. | M38: =_xlfn.XLOOKUP(L38,'Questionnaire '!$R$2:$U$2,'Questionnaire '!$R38:$U38) | N38: =IF(L38="A",2,IF(L38="B",1,0)) | O38: Soft skills | P38: =IF(N38>=1,"","À développer") | R38: Vous aimez superviser et surveiller les activités ou les tâches qui doivent être réalisées. | S38: Lorsque vous travaillez en groupe, vous aimez contrôler régulièrement l'avancée des travaux. vous avez un attrait pour la supervision. | T38: Dans un travail de groupe, vous vous concentrez plus sur votre travail que celui des autres. Vous n'aimez pas contrôler et surveiller. | U38: Dans un travail de groupe, vous vous concentrez plus sur votre travail que celui des autres. Vous n'aimez pas contrôler et surveiller. | W38: =IF(N38>0,"N","S")
A39: 36 | C39: L'agilité cognitive | D39: Management de projet | E39: Mode d'action ou style de vie (J-Organisation ou P-perception) | F39: Aptitude à s'adapter facilement aux changements et à réagir aux problématiques qui ne répondent pas à notre mode de fonctionnement mental. | G39: Imaginons que vous êtes en train de jouer à un jeu de société avec des amis. D'un coup, toutes les règles établies sont modifiées. Comment réagissez-vous ? | H39: J'arrête de jouer car il n'est pas normal de changer les règles en cours de jeu. | I39: Ce changement me perturbe et m’énerve au plus haut point. Je ne sais pas quoi faire. | J39: Je lis les nouvelles règles du jeu et j'essaie de gagner quand même. | K39: Je continue à jouer car ça pourra être amusant. | M39: =_xlfn.XLOOKUP(L39,'Questionnaire '!$R$2:$U$2,'Questionnaire '!$R39:$U39) | N39: =IF(L39="C",2,IF(L39="D",1,0)) | O39: Soft skills | P39: =IF(N39>=1,"","À développer") | R39: Vous détestez être pris de court. Vous avez d'ailleurs du mal à gérer émotionnellement avec les évènements imprévus. | S39: Vous détestez être pris de court. Vous avez d'ailleurs du mal à gérer émotionnellement avec les évènements imprévus. | T39: Vous n'êtes pas perturbé par l'apparition d'évènements imprévus. | U39: Vous n'êtes pas perturbé par l'apparition d'évènements imprévus. Vous les trouvez parfois galvanisant. | W39: =IF(N39>0,"N","S")
A40: 37 | C40: Équité | D40: Management et gestion d'équipe | E40: Prise de décision (T-pensée ou F-sentiment) | F40: Capacité à traiter les situations et les individus de manière juste et impartiale, sans parti pris. | G40: Comment pensez-vous que les richesses du monde devraient être réparties ? | H40: Les pays riches devraient aider les pays pauvres. | I40: Tout le monde devrait avoir assez pour vivre correctement. | J40: Je pense que la répartition des richesses est un reflet de la compétence et du talent individuel, et qu'il n'est pas nécessaire d'ajuster le système. | K40: Je ne crois pas qu'il soit nécessaire de redistribuer les richesses du monde ; si certains pays ou personnes sont plus riches, c'est parce qu'ils ont travaillé plus dur pour l'être. | M40: =_xlfn.XLOOKUP(L40,'Questionnaire '!$R$2:$U$2,'Questionnaire '!$R40:$U40) | N40: =IF(L40="A",2,IF(L40="B",1,0)) | O40: Soft skills | P40: =IF(N40>=1,"","À développer") | R40: Vous cherchez à être équitable dans vos choix et décisions. Surtout quand cela peut impacter la vie des gens. | S40: Vous cherchez à être équitable dans vos choix et décisions. Surtout quand cela peut impacter la vie des gens. | T40: Vous recherchez plus l'égalité de traitement à l'équité de traitement. Vous aimez que tout le monde soit traité de la même façon, peu importe leur condition. | U40: Vous recherchez plus l'égalité de traitement à l'équité de traitement. Vous aimez que tout le monde soit traité de la même façon, peu importe leur condition. | W40: =IF(N40>0,"F","T")
...

Sheet Résultat test questionnaire
B2: Analyse Soft skills | C2: Max possible | D2: Score obtenu | E2: % de maîtrise | F2: Niveau
B3: Catégorie soft skills | C3: Barème | D3: Résultat | E3: Pourcentage de réponses en accord avec la catégorie | F3: Niveau | G3: Schéma de personnalité
B4: Communication | C4: =COUNTIF('Questionnaire '!D:D,B4)*2 | D4: =SUMIF('Questionnaire '!D:D,B4,'Questionnaire '!N:N) | E4: =D4/C4 | F4: =IF(E4<0.25,"Très peu développé",IF(E4<0.5,"Peu développé",IF(E4<0.75,"Développé","Très développé"))) | G4: =D4/D12
B5: Esprit critique | C5: =COUNTIF('Questionnaire '!D:D,B5)*2 | D5: =SUMIF('Questionnaire '!D:D,B5,'Questionnaire '!N:N) | E5: =D5/C5 | F5: =IF(E5<0.25,"Très peu développé",IF(E5<0.5,"Peu développé",IF(E5<0.75,"Développé","Très développé"))) | G5: =D5/D12
B6: Ethique | C6: =COUNTIF('Questionnaire '!D:D,B6)*2 | D6: =SUMIF('Questionnaire '!D:D,B6,'Questionnaire '!N:N) | E6: =D6/C6 | F6: =IF(E6<0.25,"Très peu développé",IF(E6<0.5,"Peu développé",IF(E6<0.75,"Développé","Très développé"))) | G6: =D6/D12
B7: Intelligence émotionnelle | C7: =COUNTIF('Questionnaire '!D:D,B7)*2 | D7: =SUMIF('Questionnaire '!D:D,B7,'Questionnaire '!N:N) | E7: =D7/C7 | F7: =IF(E7<0.25,"Très peu développé",IF(E7<0.5,"Peu développé",IF(E7<0.75,"Développé","Très développé"))) | G7: =D7/D12
B8: Intelligence sociale | C8: =COUNTIF('Questionnaire '!D:D,B8)*2 | D8: =SUMIF('Questionnaire '!D:D,B8,'Questionnaire '!N:N) | E8: =D8/C8 | F8: =IF(E8<0.25,"Très peu développé",IF(E8<0.5,"Peu développé",IF(E8<0.75,"Développé","Très développé"))) | G8: =D8/D12
B9: Management de projet | C9: =COUNTIF('Questionnaire '!D:D,B9)*2 | D9: =SUMIF('Questionnaire '!D:D,B9,'Questionnaire '!N:N) | E9: =D9/C9 | F9: =IF(E9<0.25,"Très peu développé",IF(E9<0.5,"Peu développé",IF(E9<0.75,"Développé","Très développé"))) | G9: =D9/D12
B10: Management et gestion d'équipe | C10: =COUNTIF('Questionnaire '!D:D,B10)*2 | D10: =SUMIF('Questionnaire '!D:D,B10,'Questionnaire '!N:N) | E10: =D10/C10 | F10: =IF(E10<0.25,"Très peu développé",IF(E10<0.5,"Peu développé",IF(E10<0.75,"Développé","Très développé"))) | G10: =D10/D12
B11: Organisation | C11: =COUNTIF('Questionnaire '!D:D,B11)*2 | D11: =SUMIF('Questionnaire '!D:D,B11,'Questionnaire '!N:N) | E11: =D11/C11 | F11: =IF(E11<0.25,"Très peu développé",IF(E11<0.5,"Peu développé",IF(E11<0.75,"Développé","Très développé"))) | G11: =D11/D12
B12: Totaux | C12: =SUM(C4:C11) | D12: =SUM(D4:D11) | G12: =SUM(G4:G11)
B20: MBTI
B21: Résultat MBTI | C21: Score max | D21: Score obtenu | E21: % de votes | F21: Lettre dominante
B22: E — Extraversion | C22: =COUNTIF('Questionnaire '!E$3:E$74,"*Energie*")*2 | D22: =SUMPRODUCT(('Questionnaire '!W$3:W$74="E")*('Questionnaire '!N$3:N$74)) | E22: =IFERROR(D22/C22,0) | F22: =IF(E22>=E23,"E","")
B23: I — Introversion | C23: =COUNTIF('Questionnaire '!E$3:E$74,"*Energie*")*2 | D23: =SUMPRODUCT(('Questionnaire '!W$3:W$74="I")*('Questionnaire '!N$3:N$74)) | E23: =IFERROR(D23/C23,0) | F23: =IF(E23>E22,"I","")
B24: N — Intuition | C24: =COUNTIF('Questionnaire '!E$3:E$74,"*perception*")*2 | D24: =SUMPRODUCT(('Questionnaire '!W$3:W$74="N")*('Questionnaire '!N$3:N$74)) | E24: =IFERROR(D24/C24,0) | F24: =IF(E24>=E25,"N","")
B25: S — Sensation | C25: =COUNTIF('Questionnaire '!E$3:E$74,"*perception*")*2 | D25: =SUMPRODUCT(('Questionnaire '!W$3:W$74="S")*('Questionnaire '!N$3:N$74)) | E25: =IFERROR(D25/C25,0) | F25: =IF(E25>E24,"S","")
B26: F — Sentiment | C26: =COUNTIF('Questionnaire '!E$3:E$74,"*sentiment*")*2 | D26: =SUMPRODUCT(('Questionnaire '!W$3:W$74="F")*('Questionnaire '!N$3:N$74)) | E26: =IFERROR(D26/C26,0) | F26: =IF(E26>=E27,"F","")
B27: T — Pensée | C27: =COUNTIF('Questionnaire '!E$3:E$74,"*sentiment*")*2 | D27: =SUMPRODUCT(('Questionnaire '!W$3:W$74="T")*('Questionnaire '!N$3:N$74)) | E27: =IFERROR(D27/C27,0) | F27: =IF(E27>E26,"T","")
B28: J — Organisation | C28: =COUNTIF('Questionnaire '!E$3:E$74,"*style de vie*")*2 | D28: =SUMPRODUCT(('Questionnaire '!W$3:W$74="J")*('Questionnaire '!N$3:N$74)) | E28: =IFERROR(D28/C28,0) | F28: =IF(E28>=E29,"J","")
B29: P — Perception | C29: =COUNTIF('Questionnaire '!E$3:E$74,"*style de vie*")*2 | D29: =SUMPRODUCT(('Questionnaire '!W$3:W$74="P")*('Questionnaire '!N$3:N$74)) | E29: =IFERROR(D29/C29,0) | F29: =IF(E29>E28,"P","")
B30: Type MBTI final | F30: =_xlfn.TEXTJOIN("",TRUE,F22:F29)

Sheet Synthése réponses questionnaire
A2: Prénom du sujet | B2: Nom du sujet | C2: Assertivité | D2: Communication à distance | E2: Communication écrite | F2: L’audace (ou le culot) | G2: L’enthousiasme et le dynamisme | H2: L’optimisme | I2: La clarté de communication | J2: La diplomatie | K2: La négociation | L2: La persuasion | M2: La posture ou la communication non verbale | N2: L'argumentation | O2: Prestance | P2: Prise de parole en public | Q2: Rhétorique ou storytelling | R2: Actualisation des connaissances | S2: L’acuité et le discernement | T2: L’humour | U2: L’ouverture d'esprit | V2: La créativité ou l'imagination | W2: La curiosité | X2: La pensée logique | Y2: La rigueur (travail) | Z2: Le sens artistique | AA2: L'innovation | AB2: Pensée critique | AC2: Penser "out of the box" | AD2: Résolution des problèmes | AE2: Savoir rechercher pour résoudre un problème | AF2: Fiabilité | AG2: L’honnêteté | AH2: L’intégrité | AI2: La conscience professionnelle | AJ2: La courtoisie, la cordialité, l’amabilité | AK2: La loyauté | AL2: La respectabilité, la dignité, l'honneur | AM2: Le sens des responsabilité | AN2: Le sens du sacrifice | AO2: L'éco-responsabilité | AP2: L'engagement | AQ2: Ponctualité | AR2: Respect des autres (doublon tolérance) | AS2: Acceptation des retours et critiques | AT2: Equanimité | AU2: Introspection | AV2: L’authenticité ou la sincérité. | AW2: L’empathie | AX2: L’humilité | AY2: La bienveillance | AZ2: La compassion | BA2: La confiance aux autres | BB2: La confiance en soi | BC2: La gestion du stress | BD2: La maitrise de soi | BE2: La reconnaissance ou considération | BF2: La résilience | BG2: La sensibilité | BH2: Aisance relationnelle | BI2: Altruisme | BJ2: Esprit d'équipe | BK2: Intelligence culturelle | BL2: L’interaction avec les autres | BM2: La coopération, la collaboration | BN2: La présence ou l'aura | BO2: La tolérance | BP2: Le networking | BQ2: Le partage d'idées | BR2: Sociabilité | BS2: L’Autonomie | BT2: La délégation de taches | BU2: La facilitation | BV2: La gestion des risques | BW2: La prise de décision | BX2: La supervision | BY2: La tolérance au changement | BZ2: L'agilité cognitive | CA2: Equité | CB2: Gérer et résoudre les conflits | CC2: Gérer les équipes à distances | CD2: Inclusivité | CE2: L’esprit d’initiative | CF2: La valorisation ou l'encouragement | CG2: Le charisme | CH2: Le coaching des autres | CI2: Leadership | CJ2: L’auto-formation | CK2: La concentration | CL2: La fixation d'objectifs | CM2: La gestion des ressources | CN2: La gestion du temps | CO2: La hiérarchisation et la priorisation | CP2: La patiente | CQ2: La persévérance | CR2: La planification | CS2: La ponctualité | CT2: La recherche d'efficacité | CU2: La visualisation | CV2: Le respect des délais
A3: Isoline | B3: VICHITH | C3: B | D3: B | E3: B | F3: A | G3: B | H3: D | I3: B | J3: B | K3: C | L3: A | M3: B | N3: A | O3: C | P3: C | Q3: D | R3: B | S3: B | T3: D | U3: D | V3: C | W3: B | X3: A | Y3: C | Z3: D | AA3: D | AB3: C | AC3: A | AD3: C | AE3: B | AF3: D | AG3: B | AH3: A | AI3: B | AJ3: B | AK3: A | AL3: A | AM3: D | AN3: B | AO3: C | AP3: A | AQ3: B | AR3: D | AS3: B | AT3: C | AU3: C | AV3: B | AW3: B | AX3: C | AY3: C | AZ3: D | BA3: C | BB3: A | BC3: C | BD3: D | BE3: C | BF3: A | BG3: C | BH3: A | BI3: B | BJ3: B | BK3: D | BL3: B | BM3: A | BN3: C | BO3: B | BP3: A | BQ3: C | BR3: B | BS3: B | BT3: A | BU3: A | BV3: C | BW3: B | BX3: C | BY3: A | BZ3: C | CA3: B | CB3: B | CC3: C | CD3: A | CE3: C | CF3: A | CG3: A | CH3: B | CI3: B | CJ3: D | CK3: A | CL3: C | CM3: B | CN3: B | CO3: D | CP3: A | CQ3: C | CR3: A | CS3: D | CT3: D | CU3: D | CV3: D
A4: Kaïs | B4: FOFANA

Sheet PUBLIPOSTAGE 
